# 优雅的异常处理

[讨论地址](https://github.com/fengpeng/corner/issues/1)
#JS #异常处理

最近做 Code Review 时, 有许多同学不太注重异常处理.

尤其在 `async await` 语法糖的使用上. 有许多同学不太理解 `async` 函数返回了一个 `Promise` 到底意味着什么. 只是知道它返回了而已.

## 什么是异常

简单来说, 异常是在代码执行过程中出现的错误或意外情况. 比如以下可以主动抛出的错误:

```jsx
throw TypeError('this is type error!')
throw new TypeError('this is new type error!')

throw 'this is error'
```
尽量使用前两种
## 抛出异常发生了什么

异常被抛出后, 就好像我们熟知的事件流. 它会沿着调用栈向上冒泡, 除非在某个阶段处理了它.  一旦它到达最外层而又没有处理, 程序则可能崩溃.  这也是好多框架都提供一个兜底错误处理的原因.

在 `Devtools` 里会得到类似的输出:

```jsx
index.html:57 Uncaught TypeError: the day is string!
    at c (index.html:57)
    at b (index.html:56)
    at a (index.html:55)
    at main (index.html:54)
    at index.html:58
```

能较清晰的看到调用栈.

> PS: 这也是要求 **throw 一个正确对象** 的原因.

## 同步异常

简单来说就是当前执行栈里发生的错误, 也就是我们常说的, 执行同步代码时产生的错误.

```jsx
function println(content) {
  if (typeof content !== 'string') {
    throw TypeError('Wrong type');
  }
  console.log(content);
}
```

最常规的解决方式 `try...catch...finally` 

```jsx
try {
  println(1);
} catch (error) {
  console.log('error');
}
// ... other code
```

## 异步异常

如果理解了上文 "抛出异常后发生了什么" 异步的情况就很容易想明白. 简单模拟一个异步的情况:

```jsx
function failRequest() {
  window.setTimeout(() => throw Error('Someting?'), 1000);
}
```

继续理想的错误处理

```jsx
try {
  failRequest();
} catch (error) {
  console.log(error);
}
```

```jsx
VM1424:2 Uncaught Error: Someting?
    at <anonymous>:2:34
```

然而并没有捕获到这个异常. 说到底 `try/...catch` **只能捕获同步的错误**.  也就是说  `try` 语句和抛出异常的语句已经不在一个执行栈咯
## async和await

下面的代码里绕着圈定义了些异步函数:

```jsx
async function request1() {
  return new Promise((_, reject) => {
    window.setTimeout(reject, 2000);
  });
}

async function request2() {
  throw Error('request error');
  await fetch('/api/users');
  console.log('Cool!');
}

async function main() {
  try{
    request1();
    request2();
  } catch (error) {
    console.error(error);
  }
}
```

`main` 函数看起来写得很稳健. 但它还是会报错(没有捕获到), 而且还是两个错.

```jsx
VM119:8 Uncaught (in promise) Error: request error
    at request2 (<anonymous>:8:8)
    at main (<anonymous>:16:3)
    at <anonymous>:1:1

1751487:1 Uncaught (in promise) undefined
```

原理是类似的, 他们两个不在一条线上. 这个环节里修正很简单

```jsx
await request1();
await request2();
```

**使用 async 函数的地方不加 await 那就是在耍流氓**  这句话有些绝对, 但放在这个场景里完全没问题.

## 错误处理

写了几段才来到如何处理. 这里马上有同学指出应该在所有使用 `await` 的代码里都加上 `try...catch`语句. 这样说也虽然无可厚非, 但我们用 `try` 这样手段本质上为了处理可能出现的错误, 属于一种预判行为.

简而言之, 如果你的函数总是能返回一个正确的值, 就不用:

```jsx
async function request() {
  return 'request';
}

async function request1() {
  try {
    throw Error('request1 error');
    return 'KPL';
  } catch (error) {
    return 'request1'
  }
}
async function main() {
  const r = await request();
  const r1 = await request1();
  console.log(r, r1);
}

main();
```

有些同学不喜欢 `try...catch` 的原因是会形成个作用域. 需要将某些变量用 `let` 声明在上一级作用域.
恩, 很有道理, 毕竟代码不好看了(笑). 此时 由于 `async` 函数返回一个 `Promise`.  所以也可以这样处理:

```jsx
async function request() {
  return 'request';
}

async function request1() {
  throw Error('request1 error');
}
async function main() {
  const r = await request();
  const r1 = await request1().catch(() => 'request1 value');
  console.log(r, r1);
}

main() //request,  request1 value
```

好似在表达, 如果错了就请用  *request1 value* 这个字符串的感觉:

```jsx
const r1 = await request1().catch(() => 'request1 value');
```

隐约记得社区里有人称之为 **混双** 派. 不知是哪一年的事了.

还有个流派当时被称为 **转换流** . 它明显受到了 `golang` 的影响. 每次都固定返回错误和值. 和Node Callback中处理的形式大同小异:

```javascript
export default function to(promise) {
  return promise.then(data => {
    return [null, data];
  })
  .catch(err => [err]);
}

async function asyncTask() {
  let err, user, savedTask;

  [err, user] = await to(UserModel.findById(1));
  if(!user) throw new CustomerError('No user found');

  [err, savedTask] = await to(TaskModel({userId: user.id, name: 'Demo Task'}));
  if(err) throw new CustomError('Error occurred while saving task');

}
```

可能是 `golang` 做全栈的朋友玩出的花样.  我觉得就没必要了. 使用 `try...catch` 和混双足以解决问题.
## 总结

- `try...catch` 只能捕获同步的错误
- 调用 `async` 的地方一般都需要加 `await`
- `async` 函数里, return 会处理成 `resolve` 的值, throw 的异常处理成 `reject` 的值
- 如果在函数外的调用, 也可以在调用后跟 `.catch` 处理异常